Workbook

Sheet Como usar
B2: BRIGADA DE INCÊNDIO — Cronograma Geral da Gestão
B3: Gestão agosto/2026 a agosto/2027 · PROPOSTA para validação com o coordenador e os líderes
B5: Como ler | C5: Cada linha é uma atividade. Nas colunas dos meses, a letra mostra a situação da atividade naquele mês.
B6: P | C6: Prevista — está planejada para o mês.
B7: R | C7: Realizada — aconteceu (tenha a comprovação: ATA, lista de presença, checklist, fotos).
B8: A | C8: Adiada — não aconteceu no mês previsto. Marque também o novo mês com P.
B9: C | C9: Cancelada / não necessária.
B10: O que editar | C10: Só as células dos meses (escolha na lista: P, R, A ou C) e as colunas Responsável e Observação. Os totais e o % realizado são calculados sozinhos.
B11: Para validar | C11: 1) Meses sugeridos dos simulados, da SIPAT e da revisão do Plano de Emergência. 2) Se o prédio tem iluminação de emergência e alarme/detecção. 3) Meses de manutenção de mangueiras e de recarga dos extintores (conforme a empresa contratada e os vencimentos no app). 4) Responsáveis de cada atividade. 5) Se falta alguma atividade.
B12: Atenção | C12: As frequências são sugestões de boas práticas. Confirme as exigências da Instrução Técnica do Corpo de Bombeiros do estado, das normas ABNT aplicáveis e do contrato com a empresa de manutenção.
B13: Depois | C13: Validado o cronograma, ele pode ser importado para o Calendário do app, junto com as reuniões.
B15: Abas | C15: Cronograma = visão do ano (o que acontece em cada mês). Detalhes = objetivo, roteiro e comprovação de cada ação, com os temas de DDS mês a mês e o banco de temas reserva. Resumo = andamento por tipo. Lista de presença = modelo para imprimir.
B16: Navegar | C16: No Cronograma, clique em "ver ›" na coluna Detalhes para abrir a especificação da ação. Na aba Detalhes, clique no número da ação para voltar ao Cronograma.
B17: DDS | C17: Na aba Detalhes, preencha a Data realizada e o Nº de participantes de cada DDS; no Cronograma, marque R no mês.

Sheet Cronograma
A1: CRONOGRAMA GERAL DA BRIGADA — GESTÃO AGO/2026 A AGO/2027
A2: Proposta para validação · P = prevista · R = realizada · A = adiada · C = cancelada
A4: Nº | B4: Tipo | C4: Atividade | D4: Frequência | E4: Responsável | F4: Comprovação | G4: Ago/26 | H4: Set/26 | I4: Out/26 | J4: Nov/26 | K4: Dez/26 | L4: Jan/27 | M4: Fev/27 | N4: Mar/27 | O4: Abr/27 | P4: Mai/27 | Q4: Jun/27 | R4: Jul/27 | S4: Ago/27 | T4: Previstas | U4: Realizadas | V4: % realizado | W4: Observação / a validar | X4: Detalhes
A5: 1 | B5: Reuniões | C5: Reunião Geral da Brigada | D5: Mensal (3ª quarta-feira) | E5: Coordenador / Secretária | F5: ATA assinada no app | G5: R | I5: P | J5: P | K5: P | L5: P | M5: P | N5: P | O5: P | P5: P | Q5: P | R5: P | S5: P | T5: =COUNTIF(G5:S5,"P")+COUNTIF(G5:S5,"R")+COUNTIF(G5:S5,"A") -> 12 | U5: =COUNTIF(G5:S5,"R") -> 1 | V5: =IF(T5=0,"-",U5/T5) -> 0.083333333 | W5: Ago/26 realizada (26/08). Set/26 não houve. Out/26 em 22/10 (exceção: quinta-feira). | X5: ver ›
A6: 2 | B6: Reuniões | C6: Reunião de Líderes | D6: Mensal, 7 a 10 dias antes da Geral (quando necessário) | E6: Coordenador + líderes de andar | F6: ATA no app | I6: R | J6: P | K6: P | L6: P | M6: P | N6: P | O6: P | P6: P | Q6: P | R6: P | S6: P | T6: =COUNTIF(G6:S6,"P")+COUNTIF(G6:S6,"R")+COUNTIF(G6:S6,"A") -> 11 | U6: =COUNTIF(G6:S6,"R") -> 1 | V6: =IF(T6=0,"-",U6/T6) -> 0.090909091 | W6: Out/26 realizada (06/10). Pode não acontecer em todos os meses. | X6: ver ›
A7: 3 | B7: Treinamentos | C7: Formação / reciclagem da brigada (Semana de Treinamento) | D7: Anual | E7: Coordenador + empresa de treinamento | F7: Certificados (app: Documentos) | G7: R | S7: P | T7: =COUNTIF(G7:S7,"P")+COUNTIF(G7:S7,"R")+COUNTIF(G7:S7,"A") -> 2 | U7: =COUNTIF(G7:S7,"R") -> 1 | V7: =IF(T7=0,"-",U7/T7) -> 0.5 | W7: Ago/26 realizada (10 a 13/08). Ago/27: reciclagem — certificados vencem. | X7: ver ›
A8: 4 | B8: Treinamentos | C8: Integração de novos brigadistas | D8: Quando houver entrada | E8: Coordenador | F8: Lista de presença | T8: =COUNTIF(G8:S8,"P")+COUNTIF(G8:S8,"R")+COUNTIF(G8:S8,"A") -> 0 | U8: =COUNTIF(G8:S8,"R") -> 0 | V8: =IF(T8=0,"-",U8/T8) -> - | W8: Sem mês fixo: marcar quando entrar alguém novo. | X8: ver ›
A9: 5 | B9: Treinamentos | C9: DDS da Brigada (tema do mês) | D9: Mensal | E9: Líderes de andar | F9: Lista de presença | J9: P | K9: P | L9: P | M9: P | N9: P | O9: P | P9: P | Q9: P | R9: P | S9: P | T9: =COUNTIF(G9:S9,"P")+COUNTIF(G9:S9,"R")+COUNTIF(G9:S9,"A") -> 10 | U9: =COUNTIF(G9:S9,"R") -> 0 | V9: =IF(T9=0,"-",U9/T9) -> 0 | W9: Um tema por mês: temas, objetivos e roteiros na aba Detalhes (5.1 a 5.10). 1º tema: obstrução de extintor na operação. | X9: ver ›
A10: 6 | B10: Simulados | C10: Simulado de abandono de área (evacuação) | D10: Semestral (sugestão) | E10: Coordenador + líderes de evacuação | F10: Relatório, fotos, tempo de saída e lista de chamada (app: Pessoas no Prédio) | J10: P | P10: P | T10: =COUNTIF(G10:S10,"P")+COUNTIF(G10:S10,"R")+COUNTIF(G10:S10,"A") -> 2 | U10: =COUNTIF(G10:S10,"R") -> 0 | V10: =IF(T10=0,"-",U10/T10) -> 0 | W10: Meses sugeridos — validar com os líderes e com a norma aplicável. | X10: ver ›
A11: 7 | B11: Simulados | C11: Simulado prático de combate a princípio de incêndio e primeiros socorros | D11: Anual (sugestão) | E11: Coordenador + combatentes e socorristas | F11: Relatório e fotos | N11: P | T11: =COUNTIF(G11:S11,"P")+COUNTIF(G11:S11,"R")+COUNTIF(G11:S11,"A") -> 1 | U11: =COUNTIF(G11:S11,"R") -> 0 | V11: =IF(T11=0,"-",U11/T11) -> 0 | W11: Mês sugerido. | X11: ver ›
A12: 8 | B12: Inspeções | C12: Inspeção visual dos extintores | D12: Mensal | E12: Combatentes | F12: Checklist no app (Extintores) | J12: P | K12: P | L12: P | M12: P | N12: P | O12: P | P12: P | Q12: P | R12: P | S12: P | T12: =COUNTIF(G12:S12,"P")+COUNTIF(G12:S12,"R")+COUNTIF(G12:S12,"A") -> 10 | U12: =COUNTIF(G12:S12,"R") -> 0 | V12: =IF(T12=0,"-",U12/T12) -> 0 | X12: ver ›
A13: 9 | B13: Inspeções | C13: Recarga / manutenção dos extintores | D13: Anual (conforme vencimento) | E13: Empresa contratada (acompanhamento: coordenador) | F13: Etiqueta e nota da empresa | T13: =COUNTIF(G13:S13,"P")+COUNTIF(G13:S13,"R")+COUNTIF(G13:S13,"A") -> 0 | U13: =COUNTIF(G13:S13,"R") -> 0 | V13: =IF(T13=0,"-",U13/T13) -> - | W13: Marcar o mês conforme o vencimento de cada extintor no app. | X13: ver ›
A14: 10 | B14: Inspeções | C14: Inspeção visual dos hidrantes e abrigos de mangueira | D14: Mensal | E14: Combatentes | F14: Checklist no app (Hidrantes) | J14: P | K14: P | L14: P | M14: P | N14: P | O14: P | P14: P | Q14: P | R14: P | S14: P | T14: =COUNTIF(G14:S14,"P")+COUNTIF(G14:S14,"R")+COUNTIF(G14:S14,"A") -> 10 | U14: =COUNTIF(G14:S14,"R") -> 0 | V14: =IF(T14=0,"-",U14/T14) -> 0 | X14: ver ›
A15: 11 | B15: Inspeções | C15: Inspeção e manutenção das mangueiras de incêndio | D15: Semestral inspeção / anual manutenção (sugestão) | E15: Empresa contratada | F15: Laudo / relatório da empresa | M15: P | S15: P | T15: =COUNTIF(G15:S15,"P")+COUNTIF(G15:S15,"R")+COUNTIF(G15:S15,"A") -> 2 | U15: =COUNTIF(G15:S15,"R") -> 0 | V15: =IF(T15=0,"-",U15/T15) -> 0 | W15: Confirmar meses com a empresa de manutenção. | X15: ver ›
A16: 12 | B16: Inspeções | C16: Teste da iluminação de emergência | D16: Mensal | E16: Líderes de andar | F16: Checklist | J16: P | K16: P | L16: P | M16: P | N16: P | O16: P | P16: P | Q16: P | R16: P | S16: P | T16: =COUNTIF(G16:S16,"P")+COUNTIF(G16:S16,"R")+COUNTIF(G16:S16,"A") -> 10 | U16: =COUNTIF(G16:S16,"R") -> 0 | V16: =IF(T16=0,"-",U16/T16) -> 0 | W16: Confirmar se há este sistema no prédio. | X16: ver ›
A17: 13 | B17: Inspeções | C17: Teste do alarme / sistema de detecção | D17: Mensal (sugestão) | E17: Coordenador | F17: Checklist | J17: P | K17: P | L17: P | M17: P | N17: P | O17: P | P17: P | Q17: P | R17: P | S17: P | T17: =COUNTIF(G17:S17,"P")+COUNTIF(G17:S17,"R")+COUNTIF(G17:S17,"A") -> 10 | U17: =COUNTIF(G17:S17,"R") -> 0 | V17: =IF(T17=0,"-",U17/T17) -> 0 | W17: Confirmar se há este sistema no prédio. | X17: ver ›
A18: 14 | B18: Inspeções | C18: Rotas de fuga, saídas de emergência e sinalização desobstruídas | D18: Mensal | E18: Líderes de evacuação | F18: Checklist / fotos | J18: P | K18: P | L18: P | M18: P | N18: P | O18: P | P18: P | Q18: P | R18: P | S18: P | T18: =COUNTIF(G18:S18,"P")+COUNTIF(G18:S18,"R")+COUNTIF(G18:S18,"A") -> 10 | U18: =COUNTIF(G18:S18,"R") -> 0 | V18: =IF(T18=0,"-",U18/T18) -> 0 | X18: ver ›
A19: 15 | B19: Inspeções | C19: Conferência do kit de primeiros socorros | D19: Mensal | E19: Responsável pelo kit | F19: Checklist de itens e validades | J19: P | K19: P | L19: P | M19: P | N19: P | O19: P | P19: P | Q19: P | R19: P | S19: P | T19: =COUNTIF(G19:S19,"P")+COUNTIF(G19:S19,"R")+COUNTIF(G19:S19,"A") -> 10 | U19: =COUNTIF(G19:S19,"R") -> 0 | V19: =IF(T19=0,"-",U19/T19) -> 0 | X19: ver ›
A20: 16 | B20: Inspeções | C20: Ponto de encontro: placas e identificação | D20: Trimestral | E20: Líder de evacuação | F20: Fotos | J20: P | M20: P | P20: P | S20: P | T20: =COUNTIF(G20:S20,"P")+COUNTIF(G20:S20,"R")+COUNTIF(G20:S20,"A") -> 4 | U20: =COUNTIF(G20:S20,"R") -> 0 | V20: =IF(T20=0,"-",U20/T20) -> 0 | W20: Placa do ponto de encontro geral ainda pendente (ATA 22/10). | X20: ver ›
A21: 17 | B21: Pessoas e documentos | C21: Atualizar a lista de pessoas no prédio | D21: Mensal (e a cada admissão/desligamento) | E21: RH (Elizângela) | F21: Planilha importada no app (Pessoas no Prédio) | J21: P | K21: P | L21: P | M21: P | N21: P | O21: P | P21: P | Q21: P | R21: P | S21: P | T21: =COUNTIF(G21:S21,"P")+COUNTIF(G21:S21,"R")+COUNTIF(G21:S21,"A") -> 10 | U21: =COUNTIF(G21:S21,"R") -> 0 | V21: =IF(T21=0,"-",U21/T21) -> 0 | X21: ver ›
A22: 18 | B22: Pessoas e documentos | C22: Conferir validade do AVCB / CLCB e certificados | D22: Trimestral | E22: Coordenador | F22: App: Certificados e Atestado | J22: P | M22: P | P22: P | S22: P | T22: =COUNTIF(G22:S22,"P")+COUNTIF(G22:S22,"R")+COUNTIF(G22:S22,"A") -> 4 | U22: =COUNTIF(G22:S22,"R") -> 0 | V22: =IF(T22=0,"-",U22/T22) -> 0 | X22: ver ›
A23: 19 | B23: Pessoas e documentos | C23: Revisar o Plano de Emergência | D23: Anual | E23: Coordenador + líderes | F23: Plano revisado e assinado | Q23: P | T23: =COUNTIF(G23:S23,"P")+COUNTIF(G23:S23,"R")+COUNTIF(G23:S23,"A") -> 1 | U23: =COUNTIF(G23:S23,"R") -> 0 | V23: =IF(T23=0,"-",U23/T23) -> 0 | W23: Mês sugerido: antes do encerramento da gestão. | X23: ver ›
A24: 20 | B24: Campanhas | C24: SIPAT (participação da Brigada) | D24: Anual | E24: CIPA + Brigada | F24: Programação e lista de presença | O24: P | T24: =COUNTIF(G24:S24,"P")+COUNTIF(G24:S24,"R")+COUNTIF(G24:S24,"A") -> 1 | U24: =COUNTIF(G24:S24,"R") -> 0 | V24: =IF(T24=0,"-",U24/T24) -> 0 | W24: Mês A DEFINIR com a CIPA. | X24: ver ›
A25: 21 | B25: Campanhas | C25: Comunicação ao time (quadro da brigada, identificação, avisos) | D25: Trimestral | E25: Coordenador / Marketing | F25: Fotos / e-mail | J25: P | M25: P | P25: P | S25: P | T25: =COUNTIF(G25:S25,"P")+COUNTIF(G25:S25,"R")+COUNTIF(G25:S25,"A") -> 4 | U25: =COUNTIF(G25:S25,"R") -> 0 | V25: =IF(T25=0,"-",U25/T25) -> 0 | W25: Quadro geral da brigada em produção (ATA 22/10). | X25: ver ›
A26: 22 | B26: Gestão | C26: Balanço da gestão (relatório para a diretoria) | D26: Anual | E26: Coordenador + secretária | F26: Relatório | R26: P | T26: =COUNTIF(G26:S26,"P")+COUNTIF(G26:S26,"R")+COUNTIF(G26:S26,"A") -> 1 | U26: =COUNTIF(G26:S26,"R") -> 0 | V26: =IF(T26=0,"-",U26/T26) -> 0 | X26: ver ›
A27: 23 | B27: Gestão | C27: Definição da composição da próxima gestão | D27: Anual | E27: Coordenador + RH | F27: Lista de brigadistas atualizada no app | R27: P | T27: =COUNTIF(G27:S27,"P")+COUNTIF(G27:S27,"R")+COUNTIF(G27:S27,"A") -> 1 | U27: =COUNTIF(G27:S27,"R") -> 0 | V27: =IF(T27=0,"-",U27/T27) -> 0 | W27: Antes da reciclagem de Ago/27. | X27: ver ›
C29: Atividades previstas no mês | G29: =COUNTIF(G5:G27,"P")+COUNTIF(G5:G27,"R")+COUNTIF(G5:G27,"A") -> 2 | H29: =COUNTIF(H5:H27,"P")+COUNTIF(H5:H27,"R")+COUNTIF(H5:H27,"A") -> 0 | I29: =COUNTIF(I5:I27,"P")+COUNTIF(I5:I27,"R")+COUNTIF(I5:I27,"A") -> 2 | J29: =COUNTIF(J5:J27,"P")+COUNTIF(J5:J27,"R")+COUNTIF(J5:J27,"A") -> 14 | K29: =COUNTIF(K5:K27,"P")+COUNTIF(K5:K27,"R")+COUNTIF(K5:K27,"A") -> 10 | L29: =COUNTIF(L5:L27,"P")+COUNTIF(L5:L27,"R")+COUNTIF(L5:L27,"A") -> 10 | M29: =COUNTIF(M5:M27,"P")+COUNTIF(M5:M27,"R")+COUNTIF(M5:M27,"A") -> 14 | N29: =COUNTIF(N5:N27,"P")+COUNTIF(N5:N27,"R")+COUNTIF(N5:N27,"A") -> 11 | ... S29: =COUNTIF(S5:S27,"P")+COUNTIF(S5:S27,"R")+COUNTIF(S5:S27,"A") -> 15 | T29: =SUM(T5:T27) -> 126
C30: Realizadas no mês | G30: =COUNTIF(G5:G27,"R") -> 2 | H30: =COUNTIF(H5:H27,"R") -> 0 | I30: =COUNTIF(I5:I27,"R") -> 1 | J30: =COUNTIF(J5:J27,"R") -> 0 | K30: =COUNTIF(K5:K27,"R") -> 0 | L30: =COUNTIF(L5:L27,"R") -> 0 | M30: =COUNTIF(M5:M27,"R") -> 0 | N30: =COUNTIF(N5:N27,"R") -> 0 | ... S30: =COUNTIF(S5:S27,"R") -> 0 | U30: =SUM(U5:U27) -> 3
C31: % realizado no mês | G31: =IF(G29=0,"-",G30/G29) -> 1 | H31: =IF(H29=0,"-",H30/H29) -> - | I31: =IF(I29=0,"-",I30/I29) -> 0.5 | J31: =IF(J29=0,"-",J30/J29) -> 0 | K31: =IF(K29=0,"-",K30/K29) -> 0 | L31: =IF(L29=0,"-",L30/L29) -> 0 | M31: =IF(M29=0,"-",M30/M29) -> 0 | N31: =IF(N29=0,"-",N30/N29) -> 0 | ... S31: =IF(S29=0,"-",S30/S29) -> 0 | T31: Gestão: | V31: =IF(T29=0,"-",U30/T29) -> 0.023809524

Sheet Detalhes
A1: DETALHES DE CADA AÇÃO DO CRONOGRAMA
A2: Objetivo, roteiro e comprovação de cada atividade. O DDS aparece mês a mês (5.1 a 5.10). Volte ao cronograma pelo link da coluna Detalhes.
A4: Nº | B4: Tipo | C4: Atividade | D4: Mês / frequência | E4: Tema | F4: Objetivo | G4: Como fazer (roteiro) | H4: Material de apoio / comprovação | I4: Responsável | J4: Data realizada | K4: Nº participantes | L4: Observação
A5: 1 | B5: Reuniões | C5: Reunião Geral da Brigada | D5: Mensal (3ª quarta-feira) | E5: — | F5: Alinhar a brigada, apresentar as decisões e acompanhar o Plano de Ação. | G5: • Pauta vem da Reunião de Líderes • Registrar no app (Reunião Geral, modo reunião): discussão, decisão e ações por assunto • Marcar ausentes e gerar o PDF para assinaturas • Anexar a ATA assinada no app | H5: ATA assinada (app: Reunião Geral) | I5: Coordenador / Secretária | L5: Ago/26 realizada (26/08). Set/26 não houve. Out/26 em 22/10 (exceção: quinta-feira).
A6: 2 | B6: Reuniões | C6: Reunião de Líderes | D6: Mensal, 7 a 10 dias antes da Geral (quando necessário) | E6: — | F6: Preparar a Reunião Geral e decidir o que vira pauta ou ação. | G6: • Acontece de 7 a 10 dias antes da Geral • Revisar o Plano de Ação (atrasadas e próximas do prazo) • Definir a pauta e as novas ações • Registrar no app (Reunião de Líderes) | H6: ATA no app | I6: Coordenador + líderes de andar | L6: Out/26 realizada (06/10). Pode não acontecer em todos os meses.
A7: 3 | B7: Treinamentos | C7: Formação / reciclagem da brigada (Semana de Treinamento) | D7: Anual | E7: — | F7: Manter todos os brigadistas treinados e com certificado válido. | G7: • Contratar a empresa de treinamento e definir as datas • Convocar os brigadistas com antecedência • Carga horária conforme a classificação (8 h Intermediário / 24 h Avançado) • Arquivar os certificados no app (Documentos) | H7: Certificados e lista de presença | I7: Coordenador + empresa de treinamento | L7: Ago/26 realizada (10 a 13/08). Ago/27: reciclagem — certificados vencem.
A8: 4 | B8: Treinamentos | C8: Integração de novos brigadistas | D8: Quando houver entrada | E8: — | F8: Integrar quem entra na brigada durante a gestão. | G8: • Apresentar estrutura, funções, rotas de fuga e equipamentos • Cadastrar no app e incluir no quadro da brigada • Programar a formação, se ainda não tiver certificado | H8: Lista de presença / cadastro no app | I8: Coordenador | L8: Sem mês fixo: marcar quando entrar alguém novo.
A9: 5.1 | B9: Treinamentos | C9: DDS da Brigada (tema do mês) | D9: Nov/26 | E9: Extintor desobstruído na operação | F9: Garantir que todos os extintores fiquem visíveis e com acesso livre o tempo todo. | G9: • Por que o acesso livre salva tempo numa emergência (segundos contam) • Não encostar materiais, paletes, carrinhos ou peças na frente do extintor • Sinalização no chão e na parede: respeitar a área demarcada • Viu um extintor obstruído? Desobstrua ou avise o líder de andar na hora | H9: Fotos de um extintor obstruído x livre na própria área Comprovação: lista de presença assinada | I9: Líderes de andar | L9: Tema definido na Reunião de Líderes de 06/10/2026.
A10: 5.2 | B10: Treinamentos | C10: DDS da Brigada (tema do mês) | D10: Dez/26 | E10: Tipos de extintor e classes de fogo | F10: Saber escolher o extintor certo para cada tipo de fogo. | G10: • Classes de fogo: A (sólidos), B (líquidos), C (equipamentos energizados), D (metais), K (óleo de cozinha) • Extintores do prédio: água, pó químico (PQS) e CO₂ — onde estão e para que servem • Como usar: puxar o lacre, apontar para a base do fogo, apertar o gatilho, varrer • Só combater princípio de incêndio; se crescer, abandonar e acionar a brigada | H10: Um extintor de cada tipo para mostrar (sem disparar) Comprovação: lista de presença assinada | I10: Líderes de andar
A11: 5.3 | B11: Treinamentos | C11: DDS da Brigada (tema do mês) | D11: Jan/27 | E11: Trabalho a quente: solda e corte sem incêndio | F11: Prevenir incêndio em atividades com solda, corte e esmerilhamento. | G11: • Afastar ou proteger materiais combustíveis antes de começar (raio de segurança) • Ter extintor próximo e liberado durante a atividade • Fagulhas viajam: atenção a frestas, ralos e materiais embaixo • Vigiar o local por pelo menos 30 minutos depois de terminar | H11: Exemplo real de uma bancada ou área de solda da empresa Comprovação: lista de presença assinada | I11: Líderes de andar | L11: Tema ligado à atividade da empresa.
A12: 5.4 | B12: Treinamentos | C12: DDS da Brigada (tema do mês) | D12: Fev/27 | E12: Rotas de fuga e saídas de emergência | F12: Manter os caminhos de saída livres e conhecidos por todos. | G12: • Onde ficam as saídas de emergência de cada andar • Corredores, escadas e portas de saída nunca podem ficar bloqueados ou trancados • Seguir a sinalização fotoluminescente (placas verdes) • Na emergência: não usar elevador, não voltar para buscar objetos | H12: Planta do andar com as rotas marcadas Comprovação: lista de presença assinada | I12: Líderes de andar
A13: 5.5 | B13: Treinamentos | C13: DDS da Brigada (tema do mês) | D13: Mar/27 | E13: Hidrantes e mangueiras de incêndio | F13: Conhecer os hidrantes do prédio e manter os abrigos desobstruídos. | G13: • Onde ficam os hidrantes e abrigos de mangueira • Quem pode operar o hidrante (brigadistas treinados) • Abrigo sempre fechado, sinalizado e sem nada na frente • Nunca usar água em equipamentos energizados | H13: Visita rápida a um abrigo de mangueira Comprovação: lista de presença assinada | I13: Líderes de andar
A14: 5.6 | B14: Treinamentos | C14: DDS da Brigada (tema do mês) | D14: Abr/27 | E14: Abandono de área e ponto de encontro | F14: Preparar todos para o simulado de abandono de maio. | G14: • O que fazer ao ouvir o alarme ou o aviso de abandono • Papel dos líderes de evacuação e de andar • Caminho até o ponto de encontro e por que ninguém pode sair dele • Lista de chamada: como confirmamos que todos saíram | H14: Mapa com o ponto de encontro Comprovação: lista de presença assinada | I14: Líderes de andar | L14: Preparação para o simulado previsto em Mai/27.
A15: 5.7 | B15: Treinamentos | C15: DDS da Brigada (tema do mês) | D15: Mai/27 | E15: Primeiros socorros básicos | F15: Saber o que fazer (e o que não fazer) até a chegada do socorro. | G15: • Avaliar a cena: segurança primeiro • Acionar o socorrista da brigada e o SAMU (192) • Queimaduras: água corrente em temperatura ambiente; não usar pasta, manteiga ou gelo • Onde fica o kit de primeiros socorros do andar | H15: Kit de primeiros socorros do andar Comprovação: lista de presença assinada | I15: Líderes de andar | L15: Revisar o conteúdo com o socorrista da brigada.
A16: 5.8 | B16: Treinamentos | C16: DDS da Brigada (tema do mês) | D16: Jun/27 | E16: Riscos elétricos e sobrecarga | F16: Evitar incêndios de origem elétrica. | G16: • Não sobrecarregar tomadas com benjamins e extensões em cadeia • Fios descascados, aquecidos ou com cheiro de queimado: desligar e avisar a manutenção • Desligar equipamentos ao final do expediente • Em fogo em equipamento elétrico: desligar a energia e usar PQS ou CO₂ | H16: Exemplo de extensão ou tomada inadequada Comprovação: lista de presença assinada | I16: Líderes de andar
A17: 5.9 | B17: Treinamentos | C17: DDS da Brigada (tema do mês) | D17: Jul/27 | E17: Inflamáveis e cilindros de gases | F17: Armazenar e manusear com segurança produtos inflamáveis e gases. | G17: • Cilindros de oxigênio, acetileno e outros gases: sempre presos, em pé e com capacete • Manter longe de fontes de calor e de óleo/graxa (risco com oxigênio) • Inflamáveis em local ventilado, identificado e longe de faíscas • Organização e limpeza (5S) também previnem incêndio | H17: Visita à área de armazenamento de gases Comprovação: lista de presença assinada | I17: Líderes de andar | L17: Confirmar com a área responsável os pontos de armazenamento.
A18: 5.10 | B18: Treinamentos | C18: DDS da Brigada (tema do mês) | D18: Ago/27 | E18: Como acionar a brigada e balanço do ano | F18: Reforçar como pedir ajuda e fechar o ciclo da gestão. | G18: • Números de emergência: Bombeiros 193, SAMU 192 e o contato interno da brigada • Quem são os brigadistas de cada andar (quadro da brigada) • O que aprendemos nos DDS e no simulado do ano • Sugestões de temas para a próxima gestão | H18: Quadro geral da brigada Comprovação: lista de presença assinada | I18: Líderes de andar | L18: Mês da reciclagem da brigada.
A19: 6 | B19: Simulados | C19: Simulado de abandono de área (evacuação) | D19: Semestral (sugestão) | E19: — | F19: Testar o plano de abandono e medir o tempo de saída. | G19: • Planejar com os líderes: data, cenário e comunicação à diretoria • Acionar o alarme / aviso de abandono e cronometrar • Fazer a chamada no ponto de encontro (app: Pessoas no Prédio → lista de chamada) • Reunião de avaliação: lições aprendidas e ações no Plano de Ação | H19: Relatório, fotos, tempo de saída e lista de chamada | I19: Coordenador + líderes de evacuação | L19: Meses sugeridos — validar com os líderes e com a norma aplicável.
A20: 7 | B20: Simulados | C20: Simulado prático de combate a princípio de incêndio e primeiros socorros | D20: Anual (sugestão) | E20: — | F20: Praticar o combate a princípio de incêndio e o atendimento inicial. | G20: • Área externa segura e autorizada • Conduzido pela empresa de treinamento ou bombeiro civil • Cada combatente pratica o uso do extintor; socorristas praticam o atendimento • Registrar participantes e fotos | H20: Relatório e fotos | I20: Coordenador + combatentes e socorristas | L20: Mês sugerido.
A21: 8 | B21: Inspeções | C21: Inspeção visual dos extintores | D21: Mensal | E21: — | F21: Garantir que cada extintor esteja pronto para uso. | G21: • No lugar certo, sinalizado e desobstruído • Lacre e pino intactos, manômetro na faixa verde • Dentro da validade (etiqueta) • Registrar no app (Extintores); problemas viram ação no Plano | H21: Inspeção registrada no app | I21: Combatentes
A22: 9 | B22: Inspeções | C22: Recarga / manutenção dos extintores | D22: Anual (conforme vencimento) | E22: — | F22: Manter os extintores dentro da validade. | G22: • Programar com a empresa conforme os vencimentos no app • Garantir reposição enquanto os extintores estão fora • Conferir etiquetas e lacres na devolução • Atualizar as datas no app | H22: Nota/relatório da empresa e etiquetas | I22: Empresa contratada (acompanhamento: coordenador) | L22: Marcar o mês conforme o vencimento de cada extintor no app.
A23: 10 | B23: Inspeções | C23: Inspeção visual dos hidrantes e abrigos de mangueira | D23: Mensal | E23: — | F23: Garantir que os hidrantes estejam prontos para uso. | G23: • Abrigo sinalizado, fechado e sem nada na frente • Mangueira acondicionada, esguicho e chave presentes • Registro sem vazamento • Registrar no app (Hidrantes) | H23: Inspeção registrada no app | I23: Combatentes
A24: 11 | B24: Inspeções | C24: Inspeção e manutenção das mangueiras de incêndio | D24: Semestral inspeção / anual manutenção (sugestão) | E24: — | F24: Garantir mangueiras em condições de uso. | G24: • Inspeção e teste feitos pela empresa contratada • Substituir mangueiras reprovadas • Guardar o laudo | H24: Laudo da empresa | I24: Empresa contratada | L24: Confirmar meses com a empresa de manutenção.
A25: 12 | B25: Inspeções | C25: Teste da iluminação de emergência | D25: Mensal | E25: — | F25: Garantir que as rotas fiquem iluminadas se faltar energia. | G25: • Acionar o teste das luminárias (botão ou desligamento) • Conferir se todas acendem • Anotar as que falharam e pedir manutenção | H25: Checklist | I25: Líderes de andar | L25: Confirmar se há este sistema no prédio.
A26: 13 | B26: Inspeções | C26: Teste do alarme / sistema de detecção | D26: Mensal (sugestão) | E26: — | F26: Garantir que o alarme funcione e seja ouvido em todo o prédio. | G26: • Avisar as pessoas antes do teste • Testar acionadores e sirene conforme orientação da manutenção • Registrar falhas e pedir correção | H26: Checklist | I26: Coordenador | L26: Confirmar se há este sistema no prédio.
A27: 14 | B27: Inspeções | C27: Rotas de fuga, saídas de emergência e sinalização desobstruídas | D27: Mensal | E27: — | F27: Manter os caminhos de saída livres. | G27: • Percorrer as rotas de cada andar • Portas de saída destrancadas e sem obstáculos • Sinalização visível e íntegra • Fotografar e corrigir o que estiver errado | H27: Checklist e fotos | I27: Líderes de evacuação
A28: 15 | B28: Inspeções | C28: Conferência do kit de primeiros socorros | D28: Mensal | E28: — | F28: Manter o kit de primeiros socorros completo. | G28: • Conferir os itens pela lista do kit • Verificar validades • Repor o que faltar e registrar | H28: Checklist de itens e validades | I28: Responsável pelo kit
A29: 16 | B29: Inspeções | C29: Ponto de encontro: placas e identificação | D29: Trimestral | E29: — | F29: Manter o ponto de encontro identificado e livre. | G29: • Placas visíveis e em bom estado • Área livre de obstáculos e veículos • Fotografar | H29: Fotos | I29: Líder de evacuação | L29: Placa do ponto de encontro geral ainda pendente (ATA 22/10).
A30: 17 | B30: Pessoas e documentos | C30: Atualizar a lista de pessoas no prédio | D30: Mensal (e a cada admissão/desligamento) | E30: — | F30: Saber quantas pessoas estão no prédio para a chamada na evacuação. | G30: • Exportar a relação de colaboradores do RH • Importar no app (Pessoas no Prédio → Atualizar lista) • Conferir terceiros e visitantes fixos | H30: Planilha importada no app | I30: RH (Elizângela)
A31: 18 | B31: Pessoas e documentos | C31: Conferir validade do AVCB / CLCB e certificados | D31: Trimestral | E31: — | F31: Não deixar vencer licenças e certificados. | G31: • Conferir as validades no app (Certificados e Atestado) • Programar a renovação com antecedência (ex.: 90 dias) • Arquivar os novos documentos no app | H31: App: Certificados e Atestado | I31: Coordenador
A32: 19 | B32: Pessoas e documentos | C32: Revisar o Plano de Emergência | D32: Anual | E32: — | F32: Manter o Plano de Emergência atualizado. | G32: • Revisar responsáveis, rotas, contatos e ponto de encontro • Incluir as lições aprendidas dos simulados • Aprovar com o coordenador e divulgar | H32: Plano revisado e assinado | I32: Coordenador + líderes | L32: Mês sugerido: antes do encerramento da gestão.
A33: 20 | B33: Campanhas | C33: SIPAT (participação da Brigada) | D33: Anual | E33: — | F33: Levar a prevenção de incêndio para a SIPAT. | G33: • Definir com a CIPA o formato: palestra, demonstração ou estande • Escolher os brigadistas que vão participar • Registrar a presença | H33: Programação e lista de presença | I33: CIPA + Brigada | L33: Mês A DEFINIR com a CIPA.
A34: 21 | B34: Campanhas | C34: Comunicação ao time (quadro da brigada, identificação, avisos) | D34: Trimestral | E34: — | F34: Manter todos informados sobre a brigada. | G34: • Quadro da brigada atualizado e visível • Avisos por mural, e-mail ou DDS • Identificação dos brigadistas (silk na camiseta de uniforme) | H34: Fotos / e-mails | I34: Coordenador / Marketing | L34: Quadro geral da brigada em produção (ATA 22/10).
A35: 22 | B35: Gestão | C35: Balanço da gestão (relatório para a diretoria) | D35: Anual | E35: — | F35: Mostrar os resultados da gestão. | G35: • Consolidar indicadores: reuniões, DDS, simulados, inspeções e % do cronograma • Destacar conquistas e pendências • Apresentar à diretoria | H35: Relatório | I35: Coordenador + secretária
A36: 23 | B36: Gestão | C36: Definição da composição da próxima gestão | D36: Anual | E36: — | F36: Preparar a próxima gestão. | G36: • Confirmar quem continua e buscar novos voluntários • Ajustar funções e áreas de responsabilidade • Atualizar o app e planejar a reciclagem de agosto | H36: Lista de brigadistas atualizada no app | I36: Coordenador + RH | L36: Antes da reciclagem de Ago/27.
C38: DDS — participação
C39: DDS com data realizada | D39: =COUNT(J9:J18) -> 0
C40: Total de participações | D40: =SUM(K9:K18) -> 0
C41: Média de participantes por DDS | D41: =IF(COUNT(K9:K18)=0,"-",AVERAGE(K9:K18)) -> -
A44: BANCO DE TEMAS DE DDS (RESERVA)
...

Sheet Resumo
A1: RESUMO POR TIPO DE ATIVIDADE
A3: Tipo | B3: Atividades | C3: Previstas | D3: Realizadas | E3: % realizado
A4: Reuniões | B4: =COUNTIF(Cronograma!$B$5:$B$27,A4) -> 2 | C4: =SUMIF(Cronograma!$B$5:$B$27,A4,Cronograma!$T$5:$T$27) -> 23 | D4: =SUMIF(Cronograma!$B$5:$B$27,A4,Cronograma!$U$5:$U$27) -> 2 | E4: =IF(C4=0,"-",D4/C4) -> 0.086956522
A5: Treinamentos | B5: =COUNTIF(Cronograma!$B$5:$B$27,A5) -> 3 | C5: =SUMIF(Cronograma!$B$5:$B$27,A5,Cronograma!$T$5:$T$27) -> 12 | D5: =SUMIF(Cronograma!$B$5:$B$27,A5,Cronograma!$U$5:$U$27) -> 1 | E5: =IF(C5=0,"-",D5/C5) -> 0.083333333
A6: Simulados | B6: =COUNTIF(Cronograma!$B$5:$B$27,A6) -> 2 | C6: =SUMIF(Cronograma!$B$5:$B$27,A6,Cronograma!$T$5:$T$27) -> 3 | D6: =SUMIF(Cronograma!$B$5:$B$27,A6,Cronograma!$U$5:$U$27) -> 0 | E6: =IF(C6=0,"-",D6/C6) -> 0
A7: Inspeções | B7: =COUNTIF(Cronograma!$B$5:$B$27,A7) -> 9 | C7: =SUMIF(Cronograma!$B$5:$B$27,A7,Cronograma!$T$5:$T$27) -> 66 | D7: =SUMIF(Cronograma!$B$5:$B$27,A7,Cronograma!$U$5:$U$27) -> 0 | E7: =IF(C7=0,"-",D7/C7) -> 0
A8: Pessoas e documentos | B8: =COUNTIF(Cronograma!$B$5:$B$27,A8) -> 3 | C8: =SUMIF(Cronograma!$B$5:$B$27,A8,Cronograma!$T$5:$T$27) -> 15 | D8: =SUMIF(Cronograma!$B$5:$B$27,A8,Cronograma!$U$5:$U$27) -> 0 | E8: =IF(C8=0,"-",D8/C8) -> 0
A9: Campanhas | B9: =COUNTIF(Cronograma!$B$5:$B$27,A9) -> 2 | C9: =SUMIF(Cronograma!$B$5:$B$27,A9,Cronograma!$T$5:$T$27) -> 5 | D9: =SUMIF(Cronograma!$B$5:$B$27,A9,Cronograma!$U$5:$U$27) -> 0 | E9: =IF(C9=0,"-",D9/C9) -> 0
A10: Gestão | B10: =COUNTIF(Cronograma!$B$5:$B$27,A10) -> 2 | C10: =SUMIF(Cronograma!$B$5:$B$27,A10,Cronograma!$T$5:$T$27) -> 2 | D10: =SUMIF(Cronograma!$B$5:$B$27,A10,Cronograma!$U$5:$U$27) -> 0 | E10: =IF(C10=0,"-",D10/C10) -> 0
A11: Total | B11: =SUM(B4:B10) -> 23 | C11: =SUM(C4:C10) -> 126 | D11: =SUM(D4:D10) -> 3 | E11: =IF(C11=0,"-",D11/C11) -> 0.023809524

Sheet Lista de presença
A1: BRIGADA DE INCÊNDIO — LISTA DE PRESENÇA (DDS / TREINAMENTO)
A3: Atividade / tema:
A4: Data:
A5: Andar / área:
A6: Facilitador:
A8: Nº | B8: Nome | C8: Setor | D8: Assinatura
A9: 1
A10: 2
A11: 3
A12: 4
A13: 5
A14: 6
A15: 7
A16: 8
A17: 9
A18: 10
A19: 11
A20: 12
... A33: 25
